<?xml version="1.0" ?>
<robot name="leo_sim">
  <!-- LEO GAZEBO -->
  <link name="base_footprint"/>
  <link name="base_link">
    <inertial>
      <mass value="1.584994"/>
      <origin xyz="-0.019662 0.011643 -0.031802"/>
      <inertia ixx="0.01042" ixy="0.001177" ixz="-0.0008871" iyy="0.01045" iyz="0.0002226" izz="0.01817"/>
    </inertial>
    <visual>
      <geometry>
        <mesh filename="file://E:\wenjian\123\issac\Myyrmaki-Digital-Twin-Isaac-Sim-ROS2\leo_description\models\Chassis.dae"/>
      </geometry>
    </visual>
    <collision>
      <geometry>
        <mesh filename="file://E:\wenjian\123\issac\Myyrmaki-Digital-Twin-Isaac-Sim-ROS2\leo_description\models\Chassis_outline.stl"/>
      </geometry>
    </collision>
  </link>
  <link name="rocker_L_link">
    <inertial>
      <mass value="1.387336"/>
      <origin xyz="0 0.01346 -0.06506"/>
      <inertia ixx="0.002956" ixy="-0.000001489324" ixz="-0.000008103407" iyy="0.02924" iyz="0.00007112" izz="0.02832"/>
    </inertial>
    <visual>
      <geometry>
        <mesh filename="file://E:\wenjian\123\issac\Myyrmaki-Digital-Twin-Isaac-Sim-ROS2\leo_description\models\Rocker.dae"/>
      </geometry>
    </visual>
    <collision>
      <geometry>
        <mesh filename="file://E:\wenjian\123\issac\Myyrmaki-Digital-Twin-Isaac-Sim-ROS2\leo_description\models\Rocker_outline.stl"/>
      </geometry>
    </collision>
  </link>
  <link name="rocker_R_link">
    <inertial>
      <mass value="1.387336"/>
      <origin xyz="0 0.01346 -0.06506"/>
      <inertia ixx="0.002956" ixy="-0.000001489324" ixz="-0.000008103407" iyy="0.02924" iyz="0.00007112" izz="0.02832"/>
    </inertial>
    <visual>
      <geometry>
        <mesh filename="file://E:\wenjian\123\issac\Myyrmaki-Digital-Twin-Isaac-Sim-ROS2\leo_description\models\Rocker.dae"/>
      </geometry>
    </visual>
    <collision>
      <geometry>
        <mesh filename="file://E:\wenjian\123\issac\Myyrmaki-Digital-Twin-Isaac-Sim-ROS2\leo_description\models\Rocker_outline.stl"/>
      </geometry>
    </collision>
  </link>
  <link name="wheel_FL_link">
    <inertial>
      <mass value="0.283642"/>
      <origin xyz="0 0.030026 0"/>
      <inertia ixx="0.000391" ixy="0.00000123962" ixz="5.52582e-7" iyy="0.0004716" iyz="-0.000002082042" izz="0.000391"/>
    </inertial>
    <visual>
      <geometry>
        <mesh filename="file://E:\wenjian\123\issac\Myyrmaki-Digital-Twin-Isaac-Sim-ROS2\leo_description\models\WheelA.dae"/>
      </geometry>
    </visual>
    <collision>
      <origin rpy="1.5707963267948966 0 0" xyz="0 0.04485 0"/>
      <geometry>
        <cylinder length="0.07" radius="0.057"/>
      </geometry>
    </collision>
    <collision>
      <origin rpy="1.5707963267948966 0 0" xyz="0 0.04485 0"/>
      <geometry>
        <cylinder length="0.04" radius="0.0625"/>
      </geometry>
    </collision>
    <collision>
      <geometry>
        <mesh filename="file://E:\wenjian\123\issac\Myyrmaki-Digital-Twin-Isaac-Sim-ROS2\leo_description\models\Wheel_outline.stl"/>
      </geometry>
    </collision>
  </link>
  <link name="wheel_RL_link">
    <inertial>
      <mass value="0.283642"/>
      <origin xyz="0 0.030026 0"/>
      <inertia ixx="0.000391" ixy="0.00000123962" ixz="5.52582e-7" iyy="0.0004716" iyz="-0.000002082042" izz="0.000391"/>
    </inertial>
    <visual>
      <geometry>
        <mesh filename="file://E:\wenjian\123\issac\Myyrmaki-Digital-Twin-Isaac-Sim-ROS2\leo_description\models\WheelA.dae"/>
      </geometry>
    </visual>
    <collision>
      <origin rpy="1.5707963267948966 0 0" xyz="0 0.04485 0"/>
      <geometry>
        <cylinder length="0.07" radius="0.057"/>
      </geometry>
    </collision>
    <collision>
      <origin rpy="1.5707963267948966 0 0" xyz="0 0.04485 0"/>
      <geometry>
        <cylinder length="0.04" radius="0.0625"/>
      </geometry>
    </collision>
    <collision>
      <geometry>
        <mesh filename="file://E:\wenjian\123\issac\Myyrmaki-Digital-Twin-Isaac-Sim-ROS2\leo_description\models\Wheel_outline.stl"/>
      </geometry>
    </collision>
  </link>
  <link name="wheel_FR_link">
    <inertial>
      <mass value="0.283642"/>
      <origin xyz="0 0.030026 0"/>
      <inertia ixx="0.000391" ixy="0.00000123962" ixz="5.52582e-7" iyy="0.0004716" iyz="-0.000002082042" izz="0.000391"/>
    </inertial>
    <visual>
      <geometry>
        <mesh filename="file://E:\wenjian\123\issac\Myyrmaki-Digital-Twin-Isaac-Sim-ROS2\leo_description\models\WheelB.dae"/>
      </geometry>
    </visual>
    <collision>
      <origin rpy="1.5707963267948966 0 0" xyz="0 0.04485 0"/>
      <geometry>
        <cylinder length="0.07" radius="0.057"/>
      </geometry>
    </collision>
    <collision>
      <origin rpy="1.5707963267948966 0 0" xyz="0 0.04485 0"/>
      <geometry>
        <cylinder length="0.04" radius="0.0625"/>
      </geometry>
    </collision>
    <collision>
      <geometry>
        <mesh filename="file://E:\wenjian\123\issac\Myyrmaki-Digital-Twin-Isaac-Sim-ROS2\leo_description\models\Wheel_outline.stl"/>
      </geometry>
    </collision>
  </link>
  <link name="wheel_RR_link">
    <inertial>
      <mass value="0.283642"/>
      <origin xyz="0 0.030026 0"/>
      <inertia ixx="0.000391" ixy="0.00000123962" ixz="5.52582e-7" iyy="0.0004716" iyz="-0.000002082042" izz="0.000391"/>
    </inertial>
    <visual>
      <geometry>
        <mesh filename="file://E:\wenjian\123\issac\Myyrmaki-Digital-Twin-Isaac-Sim-ROS2\leo_description\models\WheelB.dae"/>
      </geometry>
    </visual>
    <collision>
      <origin rpy="1.5707963267948966 0 0" xyz="0 0.04485 0"/>
      <geometry>
        <cylinder length="0.07" radius="0.057"/>
      </geometry>
    </collision>
    <collision>
      <origin rpy="1.5707963267948966 0 0" xyz="0 0.04485 0"/>
      <geometry>
        <cylinder length="0.04" radius="0.0625"/>
      </geometry>
    </collision>
    <collision>
      <geometry>
        <mesh filename="file://E:\wenjian\123\issac\Myyrmaki-Digital-Twin-Isaac-Sim-ROS2\leo_description\models\Wheel_outline.stl"/>
      </geometry>
    </collision>
  </link>
  <link name="antenna_link">
    <inertial>
      <mass value="0.001237"/>
      <origin xyz="0 0 0.028828"/>
      <inertia ixx="2.5529e-7" ixy="0.0" ixz="0.0" iyy="2.5529e-7" iyz="0.0" izz="1.354e-8"/>
    </inertial>
    <visual>
      <geometry>
        <mesh filename="file://E:\wenjian\123\issac\Myyrmaki-Digital-Twin-Isaac-Sim-ROS2\leo_description\models\Antenna.dae"/>
      </geometry>
    </visual>
    <collision>
      <origin xyz="0 0 0.028"/>
      <geometry>
        <cylinder length="0.056" radius="0.0055"/>
      </geometry>
    </collision>
  </link>
  <link name="camera_frame"/>
  <link name="camera_optical_frame"/>
  <link name="imu_frame"/>
  <!-- JOINTS -->
  <joint name="base_joint" type="fixed">
    <origin rpy="0 0 0" xyz="0 0 0.19783"/>
    <parent link="base_footprint"/>
    <child link="base_link"/>
  </joint>
  <joint name="rocker_L_joint" type="revolute">
    <origin rpy="0 0 3.141592653589793" xyz="0.00263 0.14167 -0.04731"/>
    <parent link="base_link"/>
    <child link="rocker_L_link"/>
    <axis xyz="0 1 0"/>
    <limit effort="100.0" lower="-0.24" upper="0.24" velocity="100.0"/>
    <dynamics damping="0.1" friction="1.0"/>
  </joint>
  <joint name="rocker_R_joint" type="revolute">
    <origin rpy="0 0 0" xyz="0.00263 -0.14167 -0.04731"/>
    <parent link="base_link"/>
    <child link="rocker_R_link"/>
    <axis xyz="0 1 0"/>
    <limit effort="100.0" lower="-0.24" upper="0.24" velocity="100.0"/>
    <dynamics damping="0.1" friction="1.0"/>
    <mimic joint="rocker_L_joint"/>
  </joint>
  <joint name="wheel_FL_joint" type="continuous">
    <origin rpy="0 0 0" xyz="-0.15256 -0.08214 -0.08802"/>
    <parent link="rocker_L_link"/>
    <child link="wheel_FL_link"/>
    <axis xyz="0 -1 0"/>
    <limit effort="2.0" velocity="6.0"/>
    <dynamics damping="0.1" friction="0.3125"/>
  </joint>
  <joint name="wheel_RL_joint" type="continuous">
    <origin rpy="0 0 0" xyz="0.15256 -0.08214 -0.08802"/>
    <parent link="rocker_L_link"/>
    <child link="wheel_RL_link"/>
    <axis xyz="0 -1 0"/>
    <limit effort="2.0" velocity="6.0"/>
    <dynamics damping="0.1" friction="0.3125"/>
  </joint>
  <joint name="wheel_FR_joint" type="continuous">
    <origin rpy="0 0 0" xyz="0.15256 -0.08214 -0.08802"/>
    <parent link="rocker_R_link"/>
    <child link="wheel_FR_link"/>
    <axis xyz="0 1 0"/>
    <limit effort="2.0" velocity="6.0"/>
    <dynamics damping="0.1" friction="0.3125"/>
  </joint>
  <joint name="wheel_RR_joint" type="continuous">
    <origin rpy="0 0 0" xyz="-0.15256 -0.08214 -0.08802"/>
    <parent link="rocker_R_link"/>
    <child link="wheel_RR_link"/>
    <axis xyz="0 1 0"/>
    <limit effort="2.0" velocity="6.0"/>
    <dynamics damping="0.1" friction="0.3125"/>
  </joint>
  <joint name="antenna_joint" type="fixed">
    <origin rpy="0 0 0" xyz="-0.0052 0.056 -0.0065"/>
    <parent link="base_link"/>
    <child link="antenna_link"/>
  </joint>
  <joint name="camera_joint" type="fixed">
    <origin rpy="0 0.2094 0" xyz="0.0971 0 -0.0427"/>
    <parent link="base_link"/>
    <child link="camera_frame"/>
  </joint>
  <joint name="camera_optical_joint" type="fixed">
    <origin rpy="-1.5707963267948966 0.0 -1.5707963267948966" xyz="0 0 0"/>
    <parent link="camera_frame"/>
    <child link="camera_optical_frame"/>
  </joint>
  <joint name="imu_joint" type="fixed">
    <origin rpy="0 0 0" xyz="0.0628 -0.0314 -0.0393"/>
    <parent link="base_link"/>
    <child link="imu_frame"/>
  </joint>
  <!-- base ODE properties -->
  <gazebo reference="base_footprint">
    <kp>1e6</kp>
    <kd>1.0</kd>
    <mu1>0.3</mu1>
    <mu2>0.3</mu2>
    <minDepth>0.003</minDepth>
  </gazebo>
  <gazebo reference="base_link">
    <kp>1e6</kp>
    <kd>1.0</kd>
    <mu1>0.3</mu1>
    <mu2>0.3</mu2>
    <minDepth>0.003</minDepth>
  </gazebo>
  <!-- rocker ODE properties -->
  <gazebo reference="rocker_L_link">
    <kp>1e6</kp>
    <kd>1.0</kd>
    <mu1>0.3</mu1>
    <mu2>0.3</mu2>
    <minDepth>0.003</minDepth>
  </gazebo>
  <gazebo reference="rocker_R_link">
    <kp>1e6</kp>
    <kd>1.0</kd>
    <mu1>0.3</mu1>
    <mu2>0.3</mu2>
    <minDepth>0.003</minDepth>
  </gazebo>
  <!-- wheel ODE properties -->
  <gazebo reference="wheel_FL_link">
    <kp>1e6</kp>
    <kd>100.0</kd>
    <mu1>3.0</mu1>
    <mu2>1.0</mu2>
    <fdir1>1 0 0</fdir1>
    <minDepth>0.003</minDepth>
  </gazebo>
  <gazebo reference="wheel_FR_link">
    <kp>1e6</kp>
    <kd>100.0</kd>
    <mu1>3.0</mu1>
    <mu2>1.0</mu2>
    <fdir1>1 0 0</fdir1>
    <minDepth>0.003</minDepth>
  </gazebo>
  <gazebo reference="wheel_RL_link">
    <kp>1e6</kp>
    <kd>100.0</kd>
    <mu1>3.0</mu1>
    <mu2>1.0</mu2>
    <fdir1>1 0 0</fdir1>
    <minDepth>0.003</minDepth>
  </gazebo>
  <gazebo reference="wheel_RR_link">
    <kp>1e6</kp>
    <kd>100.0</kd>
    <mu1>3.0</mu1>
    <mu2>1.0</mu2>
    <fdir1>1 0 0</fdir1>
    <minDepth>0.003</minDepth>
  </gazebo>
  <!-- camera -->
  <gazebo reference="camera_frame">
    <sensor name="leo_camera" type="camera">
      <always_on>true</always_on>
      <update_rate>30.0</update_rate>
      <visualize>false</visualize>
      <camera name="leo_camera">
        <horizontal_fov>1.9</horizontal_fov>
        <image>
          <width>640</width>
          <height>480</height>
          <format>R8G8B8</format>
        </image>
        <clip>
          <near>0.02</near>
          <far>300</far>
        </clip>
        <noise>
          <type>gaussian</type>
          <mean>0.0</mean>
          <stddev>0.007</stddev>
        </noise>
        <distortion>
          <k1>-0.279817</k1>
          <k2>0.060321</k2>
          <k3>0.000487</k3>
          <p1>0.000310</p1>
          <p2>0.000000</p2>
          <center>0.5 0.5</center>
        </distortion>
      </camera>
      <plugin filename="libgazebo_ros_camera.so" name="camera_controller">
        <robotNamespace/>
        <cameraName>camera</cameraName>
        <imageTopicName>image_raw</imageTopicName>
        <cameraInfoTopicName>camera_info</cameraInfoTopicName>
        <frameName>camera_optical_frame</frameName>
        <distortionK1>-0.279817</distortionK1>
        <distortionK2>0.060321</distortionK2>
        <distortionK3>0.000487</distortionK3>
        <distortionT1>0.000310</distortionT1>
        <distortionT2>0.000000</distortionT2>
      </plugin>
    </sensor>
  </gazebo>
  <!-- rocker differential -->
  <gazebo>
    <plugin filename="libleo_gazebo_differential_plugin.so" name="rocker_differential">
      <jointA>rocker_L_joint</jointA>
      <jointB>rocker_R_joint</jointB>
      <forceConstant>100.0</forceConstant>
    </plugin>
  </gazebo>
  <gazebo reference="imu_frame">
    <sensor name="leo_imu_sensor" type="imu">
      <update_rate>100</update_rate>
      <plugin filename="libgazebo_ros_imu_sensor.so" name="imu_plugin">
        <robotNamespace/>
        <topicName>imu/data_raw</topicName>
        <frameName>imu_frame</frameName>
        <updateRateHZ>100.0</updateRateHZ>
        <gaussianNoise>0.01</gaussianNoise>
        <initialOrientationAsReference>false</initialOrientationAsReference>
      </plugin>
    </sensor>
  </gazebo>
  <!-- ros_control plugin -->
  <gazebo>
    <plugin filename="libgazebo_ros_control.so" name="gazebo_ros_control">
      <robotNamespace/>
      <robotSimType>gazebo_ros_control/DefaultRobotHWSim</robotSimType>
    </plugin>
  </gazebo>
  <transmission name="wheel_FL_trans">
    <type>transmission_interface/SimpleTransmission</type>
    <joint name="wheel_FL_joint">
      <hardwareInterface>hardware_interface/VelocityJointInterface</hardwareInterface>
    </joint>
    <actuator name="wheel_FL_motor">
      <mechanicalReduction>1</mechanicalReduction>
      <hardwareInterface>hardware_interface/VelocityJointInterface</hardwareInterface>
    </actuator>
  </transmission>
  <transmission name="wheel_RL_trans">
    <type>transmission_interface/SimpleTransmission</type>
    <joint name="wheel_RL_joint">
      <hardwareInterface>hardware_interface/VelocityJointInterface</hardwareInterface>
    </joint>
    <actuator name="wheel_RL_motor">
      <mechanicalReduction>1</mechanicalReduction>
      <hardwareInterface>hardware_interface/VelocityJointInterface</hardwareInterface>
    </actuator>
  </transmission>
  <transmission name="wheel_FR_trans">
    <type>transmission_interface/SimpleTransmission</type>
    <joint name="wheel_FR_joint">
      <hardwareInterface>hardware_interface/VelocityJointInterface</hardwareInterface>
    </joint>
    <actuator name="wheel_FR_motor">
      <mechanicalReduction>1</mechanicalReduction>
      <hardwareInterface>hardware_interface/VelocityJointInterface</hardwareInterface>
    </actuator>
  </transmission>
  <transmission name="wheel_RR_trans">
    <type>transmission_interface/SimpleTransmission</type>
    <joint name="wheel_RR_joint">
      <hardwareInterface>hardware_interface/VelocityJointInterface</hardwareInterface>
    </joint>
    <actuator name="wheel_RR_motor">
      <mechanicalReduction>1</mechanicalReduction>
      <hardwareInterface>hardware_interface/VelocityJointInterface</hardwareInterface>
    </actuator>
  </transmission>
  <transmission name="rocker_L_trans">
    <type>transmission_interface/SimpleTransmission</type>
    <joint name="rocker_L_joint">
      <hardwareInterface>hardware_interface/EffortJointInterface</hardwareInterface>
    </joint>
    <actuator name="rocker_L_virtual_motor"/>
  </transmission>
  <transmission name="rocker_R_trans">
    <type>transmission_interface/SimpleTransmission</type>
    <joint name="rocker_R_joint">
      <hardwareInterface>hardware_interface/EffortJointInterface</hardwareInterface>
    </joint>
    <actuator name="rocker_R_virtual_motor"/>
  </transmission>
</robot>
